2024-05-03 00:41:51|ERROR   |apscheduler.executors.default   |Job "Sync with Radarr (trigger: interval[1:00:00], next run at: 2024-05-03 01:41:51 CEST)" raised an exception|'Traceback (most recent call last):\n  File "/app/bin/bazarr/../libs/apscheduler/executors/base.py", line 125, in run_job\n    retval = job.func(*job.args, **job.kwargs)\n             ^^^^^^^^^^^^^^^^^^^^^^^^^^^^^^^^^\n  File "/app/bin/bazarr/radarr/sync/movies.py", line 196, in update_movies\n    trace(f"Skipped {files_missing} file missing movies out of {i}")\n          ^^^^^^^^^^^^^^^^^^^^^^^^^^^^^^^^^^^^^^^^^^^^^^^^^^^^^^^^^\nUnboundLocalError: cannot access local variable \'i\' where it is not associated with a value'|
2024-05-03 01:41:51|ERROR   |apscheduler.executors.default   |Job "Sync with Radarr (trigger: interval[1:00:00], next run at: 2024-05-03 02:41:51 CEST)" raised an exception|'Traceback (most recent call last):\n  File "/app/bin/bazarr/../libs/apscheduler/executors/base.py", line 125, in run_job\n    retval = job.func(*job.args, **job.kwargs)\n             ^^^^^^^^^^^^^^^^^^^^^^^^^^^^^^^^^\n  File "/app/bin/bazarr/radarr/sync/movies.py", line 196, in update_movies\n    trace(f"Skipped {files_missing} file missing movies out of {i}")\n          ^^^^^^^^^^^^^^^^^^^^^^^^^^^^^^^^^^^^^^^^^^^^^^^^^^^^^^^^^\nUnboundLocalError: cannot access local variable \'i\' where it is not associated with a value'|
2024-05-03 02:41:51|ERROR   |apscheduler.executors.default   |Job "Sync with Radarr (trigger: interval[1:00:00], next run at: 2024-05-03 03:41:51 CEST)" raised an exception|'Traceback (most recent call last):\n  File "/app/bin/bazarr/../libs/apscheduler/executors/base.py", line 125, in run_job\n    retval = job.func(*job.args, **job.kwargs)\n             ^^^^^^^^^^^^^^^^^^^^^^^^^^^^^^^^^\n  File "/app/bin/bazarr/radarr/sync/movies.py", line 196, in update_movies\n    trace(f"Skipped {files_missing} file missing movies out of {i}")\n          ^^^^^^^^^^^^^^^^^^^^^^^^^^^^^^^^^^^^^^^^^^^^^^^^^^^^^^^^^\nUnboundLocalError: cannot access local variable \'i\' where it is not associated with a value'|
2024-05-03 03:35:54|INFO    |root                            |BAZARR Finished searching for missing Movies Subtitles. Check History for more information.|
2024-05-03 03:41:51|ERROR   |apscheduler.executors.default   |Job "Sync with Radarr (trigger: interval[1:00:00], next run at: 2024-05-03 04:41:51 CEST)" raised an exception|'Traceback (most recent call last):\n  File "/app/bin/bazarr/../libs/apscheduler/executors/base.py", line 125, in run_job\n    retval = job.func(*job.args, **job.kwargs)\n             ^^^^^^^^^^^^^^^^^^^^^^^^^^^^^^^^^\n  File "/app/bin/bazarr/radarr/sync/movies.py", line 196, in update_movies\n    trace(f"Skipped {files_missing} file missing movies out of {i}")\n          ^^^^^^^^^^^^^^^^^^^^^^^^^^^^^^^^^^^^^^^^^^^^^^^^^^^^^^^^^\nUnboundLocalError: cannot access local variable \'i\' where it is not associated with a value'|
2024-05-03 04:00:00|INFO    |root                            |BAZARR All existing movie subtitles indexed from disk.|
2024-05-03 04:00:00|INFO    |root                            |BAZARR All existing episode subtitles indexed from disk.|
2024-05-03 04:09:44|INFO    |root                            |BAZARR Finished searching for missing Series Subtitles. Check History for more information.|
2024-05-03 04:41:51|ERROR   |apscheduler.executors.default   |Job "Sync with Radarr (trigger: interval[1:00:00], next run at: 2024-05-03 05:41:51 CEST)" raised an exception|'Traceback (most recent call last):\n  File "/app/bin/bazarr/../libs/apscheduler/executors/base.py", line 125, in run_job\n    retval = job.func(*job.args, **job.kwargs)\n             ^^^^^^^^^^^^^^^^^^^^^^^^^^^^^^^^^\n  File "/app/bin/bazarr/radarr/sync/movies.py", line 196, in update_movies\n    trace(f"Skipped {files_missing} file missing movies out of {i}")\n          ^^^^^^^^^^^^^^^^^^^^^^^^^^^^^^^^^^^^^^^^^^^^^^^^^^^^^^^^^\nUnboundLocalError: cannot access local variable \'i\' where it is not associated with a value'|
2024-05-03 05:41:51|ERROR   |apscheduler.executors.default   |Job "Sync with Radarr (trigger: interval[1:00:00], next run at: 2024-05-03 06:41:51 CEST)" raised an exception|'Traceback (most recent call last):\n  File "/app/bin/bazarr/../libs/apscheduler/executors/base.py", line 125, in run_job\n    retval = job.func(*job.args, **job.kwargs)\n             ^^^^^^^^^^^^^^^^^^^^^^^^^^^^^^^^^\n  File "/app/bin/bazarr/radarr/sync/movies.py", line 196, in update_movies\n    trace(f"Skipped {files_missing} file missing movies out of {i}")\n          ^^^^^^^^^^^^^^^^^^^^^^^^^^^^^^^^^^^^^^^^^^^^^^^^^^^^^^^^^\nUnboundLocalError: cannot access local variable \'i\' where it is not associated with a value'|
2024-05-03 06:32:24|INFO    |root                            |BAZARR Running cache maintenance|
2024-05-03 06:41:51|ERROR   |apscheduler.executors.default   |Job "Sync with Radarr (trigger: interval[1:00:00], next run at: 2024-05-03 07:41:51 CEST)" raised an exception|'Traceback (most recent call last):\n  File "/app/bin/bazarr/../libs/apscheduler/executors/base.py", line 125, in run_job\n    retval = job.func(*job.args, **job.kwargs)\n             ^^^^^^^^^^^^^^^^^^^^^^^^^^^^^^^^^\n  File "/app/bin/bazarr/radarr/sync/movies.py", line 196, in update_movies\n    trace(f"Skipped {files_missing} file missing movies out of {i}")\n          ^^^^^^^^^^^^^^^^^^^^^^^^^^^^^^^^^^^^^^^^^^^^^^^^^^^^^^^^^\nUnboundLocalError: cannot access local variable \'i\' where it is not associated with a value'|
2024-05-03 07:41:51|ERROR   |apscheduler.executors.default   |Job "Sync with Radarr (trigger: interval[1:00:00], next run at: 2024-05-03 08:41:51 CEST)" raised an exception|'Traceback (most recent call last):\n  File "/app/bin/bazarr/../libs/apscheduler/executors/base.py", line 125, in run_job\n    retval = job.func(*job.args, **job.kwargs)\n             ^^^^^^^^^^^^^^^^^^^^^^^^^^^^^^^^^\n  File "/app/bin/bazarr/radarr/sync/movies.py", line 196, in update_movies\n    trace(f"Skipped {files_missing} file missing movies out of {i}")\n          ^^^^^^^^^^^^^^^^^^^^^^^^^^^^^^^^^^^^^^^^^^^^^^^^^^^^^^^^^\nUnboundLocalError: cannot access local variable \'i\' where it is not associated with a value'|
2024-05-03 08:05:43|INFO    |root                            |BAZARR Finished searching for Subtitles to upgrade. Check History for more information.|
2024-05-03 08:41:51|ERROR   |apscheduler.executors.default   |Job "Sync with Radarr (trigger: interval[1:00:00], next run at: 2024-05-03 09:41:51 CEST)" raised an exception|'Traceback (most recent call last):\n  File "/app/bin/bazarr/../libs/apscheduler/executors/base.py", line 125, in run_job\n    retval = job.func(*job.args, **job.kwargs)\n             ^^^^^^^^^^^^^^^^^^^^^^^^^^^^^^^^^\n  File "/app/bin/bazarr/radarr/sync/movies.py", line 196, in update_movies\n    trace(f"Skipped {files_missing} file missing movies out of {i}")\n          ^^^^^^^^^^^^^^^^^^^^^^^^^^^^^^^^^^^^^^^^^^^^^^^^^^^^^^^^^\nUnboundLocalError: cannot access local variable \'i\' where it is not associated with a value'|
2024-05-03 09:35:54|INFO    |root                            |BAZARR Finished searching for missing Movies Subtitles. Check History for more information.|
2024-05-03 09:41:51|ERROR   |apscheduler.executors.default   |Job "Sync with Radarr (trigger: interval[1:00:00], next run at: 2024-05-03 10:41:51 CEST)" raised an exception|'Traceback (most recent call last):\n  File "/app/bin/bazarr/../libs/apscheduler/executors/base.py", line 125, in run_job\n    retval = job.func(*job.args, **job.kwargs)\n             ^^^^^^^^^^^^^^^^^^^^^^^^^^^^^^^^^\n  File "/app/bin/bazarr/radarr/sync/movies.py", line 196, in update_movies\n    trace(f"Skipped {files_missing} file missing movies out of {i}")\n          ^^^^^^^^^^^^^^^^^^^^^^^^^^^^^^^^^^^^^^^^^^^^^^^^^^^^^^^^^\nUnboundLocalError: cannot access local variable \'i\' where it is not associated with a value'|
2024-05-03 10:09:44|INFO    |root                            |BAZARR Finished searching for missing Series Subtitles. Check History for more information.|
2024-05-03 10:41:51|ERROR   |apscheduler.executors.default   |Job "Sync with Radarr (trigger: interval[1:00:00], next run at: 2024-05-03 11:41:51 CEST)" raised an exception|'Traceback (most recent call last):\n  File "/app/bin/bazarr/../libs/apscheduler/executors/base.py", line 125, in run_job\n    retval = job.func(*job.args, **job.kwargs)\n             ^^^^^^^^^^^^^^^^^^^^^^^^^^^^^^^^^\n  File "/app/bin/bazarr/radarr/sync/movies.py", line 196, in update_movies\n    trace(f"Skipped {files_missing} file missing movies out of {i}")\n          ^^^^^^^^^^^^^^^^^^^^^^^^^^^^^^^^^^^^^^^^^^^^^^^^^^^^^^^^^\nUnboundLocalError: cannot access local variable \'i\' where it is not associated with a value'|
2024-05-03 11:41:51|ERROR   |apscheduler.executors.default   |Job "Sync with Radarr (trigger: interval[1:00:00], next run at: 2024-05-03 12:41:51 CEST)" raised an exception|'Traceback (most recent call last):\n  File "/app/bin/bazarr/../libs/apscheduler/executors/base.py", line 125, in run_job\n    retval = job.func(*job.args, **job.kwargs)\n             ^^^^^^^^^^^^^^^^^^^^^^^^^^^^^^^^^\n  File "/app/bin/bazarr/radarr/sync/movies.py", line 196, in update_movies\n    trace(f"Skipped {files_missing} file missing movies out of {i}")\n          ^^^^^^^^^^^^^^^^^^^^^^^^^^^^^^^^^^^^^^^^^^^^^^^^^^^^^^^^^\nUnboundLocalError: cannot access local variable \'i\' where it is not associated with a value'|
2024-05-03 12:41:51|ERROR   |apscheduler.executors.default   |Job "Sync with Radarr (trigger: interval[1:00:00], next run at: 2024-05-03 13:41:51 CEST)" raised an exception|'Traceback (most recent call last):\n  File "/app/bin/bazarr/../libs/apscheduler/executors/base.py", line 125, in run_job\n    retval = job.func(*job.args, **job.kwargs)\n             ^^^^^^^^^^^^^^^^^^^^^^^^^^^^^^^^^\n  File "/app/bin/bazarr/radarr/sync/movies.py", line 196, in update_movies\n    trace(f"Skipped {files_missing} file missing movies out of {i}")\n          ^^^^^^^^^^^^^^^^^^^^^^^^^^^^^^^^^^^^^^^^^^^^^^^^^^^^^^^^^\nUnboundLocalError: cannot access local variable \'i\' where it is not associated with a value'|
2024-05-03 13:41:51|ERROR   |apscheduler.executors.default   |Job "Sync with Radarr (trigger: interval[1:00:00], next run at: 2024-05-03 14:41:51 CEST)" raised an exception|'Traceback (most recent call last):\n  File "/app/bin/bazarr/../libs/apscheduler/executors/base.py", line 125, in run_job\n    retval = job.func(*job.args, **job.kwargs)\n             ^^^^^^^^^^^^^^^^^^^^^^^^^^^^^^^^^\n  File "/app/bin/bazarr/radarr/sync/movies.py", line 196, in update_movies\n    trace(f"Skipped {files_missing} file missing movies out of {i}")\n          ^^^^^^^^^^^^^^^^^^^^^^^^^^^^^^^^^^^^^^^^^^^^^^^^^^^^^^^^^\nUnboundLocalError: cannot access local variable \'i\' where it is not associated with a value'|
2024-05-03 14:41:51|ERROR   |apscheduler.executors.default   |Job "Sync with Radarr (trigger: interval[1:00:00], next run at: 2024-05-03 15:41:51 CEST)" raised an exception|'Traceback (most recent call last):\n  File "/app/bin/bazarr/../libs/apscheduler/executors/base.py", line 125, in run_job\n    retval = job.func(*job.args, **job.kwargs)\n             ^^^^^^^^^^^^^^^^^^^^^^^^^^^^^^^^^\n  File "/app/bin/bazarr/radarr/sync/movies.py", line 196, in update_movies\n    trace(f"Skipped {files_missing} file missing movies out of {i}")\n          ^^^^^^^^^^^^^^^^^^^^^^^^^^^^^^^^^^^^^^^^^^^^^^^^^^^^^^^^^\nUnboundLocalError: cannot access local variable \'i\' where it is not associated with a value'|
2024-05-03 15:35:54|INFO    |root                            |BAZARR Finished searching for missing Movies Subtitles. Check History for more information.|
2024-05-03 15:41:51|ERROR   |apscheduler.executors.default   |Job "Sync with Radarr (trigger: interval[1:00:00], next run at: 2024-05-03 16:41:51 CEST)" raised an exception|'Traceback (most recent call last):\n  File "/app/bin/bazarr/../libs/apscheduler/executors/base.py", line 125, in run_job\n    retval = job.func(*job.args, **job.kwargs)\n             ^^^^^^^^^^^^^^^^^^^^^^^^^^^^^^^^^\n  File "/app/bin/bazarr/radarr/sync/movies.py", line 196, in update_movies\n    trace(f"Skipped {files_missing} file missing movies out of {i}")\n          ^^^^^^^^^^^^^^^^^^^^^^^^^^^^^^^^^^^^^^^^^^^^^^^^^^^^^^^^^\nUnboundLocalError: cannot access local variable \'i\' where it is not associated with a value'|
2024-05-03 16:09:44|INFO    |root                            |BAZARR Finished searching for missing Series Subtitles. Check History for more information.|
2024-05-03 16:41:51|ERROR   |apscheduler.executors.default   |Job "Sync with Radarr (trigger: interval[1:00:00], next run at: 2024-05-03 17:41:51 CEST)" raised an exception|'Traceback (most recent call last):\n  File "/app/bin/bazarr/../libs/apscheduler/executors/base.py", line 125, in run_job\n    retval = job.func(*job.args, **job.kwargs)\n             ^^^^^^^^^^^^^^^^^^^^^^^^^^^^^^^^^\n  File "/app/bin/bazarr/radarr/sync/movies.py", line 196, in update_movies\n    trace(f"Skipped {files_missing} file missing movies out of {i}")\n          ^^^^^^^^^^^^^^^^^^^^^^^^^^^^^^^^^^^^^^^^^^^^^^^^^^^^^^^^^\nUnboundLocalError: cannot access local variable \'i\' where it is not associated with a value'|
2024-05-03 17:41:51|ERROR   |apscheduler.executors.default   |Job "Sync with Radarr (trigger: interval[1:00:00], next run at: 2024-05-03 18:41:51 CEST)" raised an exception|'Traceback (most recent call last):\n  File "/app/bin/bazarr/../libs/apscheduler/executors/base.py", line 125, in run_job\n    retval = job.func(*job.args, **job.kwargs)\n             ^^^^^^^^^^^^^^^^^^^^^^^^^^^^^^^^^\n  File "/app/bin/bazarr/radarr/sync/movies.py", line 196, in update_movies\n    trace(f"Skipped {files_missing} file missing movies out of {i}")\n          ^^^^^^^^^^^^^^^^^^^^^^^^^^^^^^^^^^^^^^^^^^^^^^^^^^^^^^^^^\nUnboundLocalError: cannot access local variable \'i\' where it is not associated with a value'|
2024-05-03 18:13:02|ERROR   |root                            |Error trying to get announcements from Github. Connection Error.|'Traceback (most recent call last):\n  File "/app/bin/bazarr/../libs/urllib3/connection.py", line 174, in _new_conn\n    conn = connection.create_connection(\n           ^^^^^^^^^^^^^^^^^^^^^^^^^^^^^\n  File "/app/bin/bazarr/../libs/subliminal_patch/http.py", line 325, in patched_create_connection\n    return _orig_create_connection(address, *args, **kwargs)\n           ^^^^^^^^^^^^^^^^^^^^^^^^^^^^^^^^^^^^^^^^^^^^^^^^^\n  File "/app/bin/bazarr/../libs/urllib3/util/connection.py", line 72, in create_connection\n    for res in socket.getaddrinfo(host, port, family, socket.SOCK_STREAM):\n               ^^^^^^^^^^^^^^^^^^^^^^^^^^^^^^^^^^^^^^^^^^^^^^^^^^^^^^^^^^\n  File "/usr/lib/python3.11/socket.py", line 962, in getaddrinfo\n    for res in _socket.getaddrinfo(host, port, family, type, proto, flags):\n               ^^^^^^^^^^^^^^^^^^^^^^^^^^^^^^^^^^^^^^^^^^^^^^^^^^^^^^^^^^^\nsocket.gaierror: [Errno -3] Try again\n\nDuring handling of the above exception, another exception occurred:\n\nTraceback (most recent call last):\n  File "/app/bin/bazarr/../libs/urllib3/connectionpool.py", line 703, in urlopen\n    httplib_response = self._make_request(\n                       ^^^^^^^^^^^^^^^^^^^\n  File "/app/bin/bazarr/../libs/urllib3/connectionpool.py", line 386, in _make_request\n    self._validate_conn(conn)\n  File "/app/bin/bazarr/../libs/urllib3/connectionpool.py", line 1042, in _validate_conn\n    conn.connect()\n  File "/app/bin/bazarr/../libs/urllib3/connection.py", line 358, in connect\n    self.sock = conn = self._new_conn()\n                       ^^^^^^^^^^^^^^^^\n  File "/app/bin/bazarr/../libs/urllib3/connection.py", line 186, in _new_conn\n    raise NewConnectionError(\nurllib3.exceptions.NewConnectionError: <urllib3.connection.HTTPSConnection object at 0x7fff728f7910>: Failed to establish a new connection: [Errno -3] Try again\n\nDuring handling of the above exception, another exception occurred:\n\nTraceback (most recent call last):\n  File "/app/bin/bazarr/../libs/requests/adapters.py", line 489, in send\n    resp = conn.urlopen(\n           ^^^^^^^^^^^^^\n  File "/app/bin/bazarr/../libs/urllib3/connectionpool.py", line 787, in urlopen\n    retries = retries.increment(\n              ^^^^^^^^^^^^^^^^^^\n  File "/app/bin/bazarr/../libs/urllib3/util/retry.py", line 592, in increment\n    raise MaxRetryError(_pool, url, error or ResponseError(cause))\nurllib3.exceptions.MaxRetryError: HTTPSConnectionPool(host=\'raw.githubusercontent.com\', port=443): Max retries exceeded with url: /morpheus65535/bazarr-binaries/master/announcements.json (Caused by NewConnectionError(\'<urllib3.connection.HTTPSConnection object at 0x7fff728f7910>: Failed to establish a new connection: [Errno -3] Try again\'))\n\nDuring handling of the above exception, another exception occurred:\n\nTraceback (most recent call last):\n  File "/app/bin/bazarr/app/announcements.py", line 46, in get_announcements_to_file\n    r = requests.get("https://raw.githubusercontent.com/morpheus65535/bazarr-binaries/master/announcements.json",\n        ^^^^^^^^^^^^^^^^^^^^^^^^^^^^^^^^^^^^^^^^^^^^^^^^^^^^^^^^^^^^^^^^^^^^^^^^^^^^^^^^^^^^^^^^^^^^^^^^^^^^^^^^^\n  File "/app/bin/bazarr/../libs/requests/api.py", line 73, in get\n    return request("get", url, params=params, **kwargs)\n           ^^^^^^^^^^^^^^^^^^^^^^^^^^^^^^^^^^^^^^^^^^^^\n  File "/app/bin/bazarr/../libs/requests/api.py", line 59, in request\n    return session.request(method=method, url=url, **kwargs)\n           ^^^^^^^^^^^^^^^^^^^^^^^^^^^^^^^^^^^^^^^^^^^^^^^^^\n  File "/app/bin/bazarr/../libs/requests/sessions.py", line 587, in request\n    resp = self.send(prep, **send_kwargs)\n           ^^^^^^^^^^^^^^^^^^^^^^^^^^^^^^\n  File "/app/bin/bazarr/../libs/requests/sessions.py", line 701, in send\n    r = adapter.send(request, **kwargs)\n        ^^^^^^^^^^^^^^^^^^^^^^^^^^^^^^^\n  File "/app/bin/bazarr/../libs/requests/adapters.py", line 565, in send\n    raise ConnectionError(e, request=request)\nrequests.exceptions.ConnectionError: HTTPSConnectionPool(host=\'raw.githubusercontent.com\', port=443): Max retries exceeded with url: /morpheus65535/bazarr-binaries/master/announcements.json (Caused by NewConnectionError(\'<urllib3.connection.HTTPSConnection object at 0x7fff728f7910>: Failed to establish a new connection: [Errno -3] Try again\'))'|
2024-05-03 18:13:07|ERROR   |root                            |Error trying to get releases from Github. Connection Error.|'Traceback (most recent call last):\n  File "/app/bin/bazarr/../libs/urllib3/connection.py", line 174, in _new_conn\n    conn = connection.create_connection(\n           ^^^^^^^^^^^^^^^^^^^^^^^^^^^^^\n  File "/app/bin/bazarr/../libs/subliminal_patch/http.py", line 325, in patched_create_connection\n    return _orig_create_connection(address, *args, **kwargs)\n           ^^^^^^^^^^^^^^^^^^^^^^^^^^^^^^^^^^^^^^^^^^^^^^^^^\n  File "/app/bin/bazarr/../libs/urllib3/util/connection.py", line 72, in create_connection\n    for res in socket.getaddrinfo(host, port, family, socket.SOCK_STREAM):\n               ^^^^^^^^^^^^^^^^^^^^^^^^^^^^^^^^^^^^^^^^^^^^^^^^^^^^^^^^^^\n  File "/usr/lib/python3.11/socket.py", line 962, in getaddrinfo\n    for res in _socket.getaddrinfo(host, port, family, type, proto, flags):\n               ^^^^^^^^^^^^^^^^^^^^^^^^^^^^^^^^^^^^^^^^^^^^^^^^^^^^^^^^^^^\nsocket.gaierror: [Errno -3] Try again\n\nDuring handling of the above exception, another exception occurred:\n\nTraceback (most recent call last):\n  File "/app/bin/bazarr/../libs/urllib3/connectionpool.py", line 703, in urlopen\n    httplib_response = self._make_request(\n                       ^^^^^^^^^^^^^^^^^^^\n  File "/app/bin/bazarr/../libs/urllib3/connectionpool.py", line 386, in _make_request\n    self._validate_conn(conn)\n  File "/app/bin/bazarr/../libs/urllib3/connectionpool.py", line 1042, in _validate_conn\n    conn.connect()\n  File "/app/bin/bazarr/../libs/urllib3/connection.py", line 358, in connect\n    self.sock = conn = self._new_conn()\n                       ^^^^^^^^^^^^^^^^\n  File "/app/bin/bazarr/../libs/urllib3/connection.py", line 186, in _new_conn\n    raise NewConnectionError(\nurllib3.exceptions.NewConnectionError: <urllib3.connection.HTTPSConnection object at 0x7fff726fb4d0>: Failed to establish a new connection: [Errno -3] Try again\n\nDuring handling of the above exception, another exception occurred:\n\nTraceback (most recent call last):\n  File "/app/bin/bazarr/../libs/requests/adapters.py", line 489, in send\n    resp = conn.urlopen(\n           ^^^^^^^^^^^^^\n  File "/app/bin/bazarr/../libs/urllib3/connectionpool.py", line 787, in urlopen\n    retries = retries.increment(\n              ^^^^^^^^^^^^^^^^^^\n  File "/app/bin/bazarr/../libs/urllib3/util/retry.py", line 592, in increment\n    raise MaxRetryError(_pool, url, error or ResponseError(cause))\nurllib3.exceptions.MaxRetryError: HTTPSConnectionPool(host=\'api.github.com\', port=443): Max retries exceeded with url: /repos/morpheus65535/Bazarr/releases?per_page=100 (Caused by NewConnectionError(\'<urllib3.connection.HTTPSConnection object at 0x7fff726fb4d0>: Failed to establish a new connection: [Errno -3] Try again\'))\n\nDuring handling of the above exception, another exception occurred:\n\nTraceback (most recent call last):\n  File "/app/bin/bazarr/app/check_update.py", line 28, in check_releases\n    r = requests.get(url_releases, allow_redirects=True)\n        ^^^^^^^^^^^^^^^^^^^^^^^^^^^^^^^^^^^^^^^^^^^^^^^^\n  File "/app/bin/bazarr/../libs/requests/api.py", line 73, in get\n    return request("get", url, params=params, **kwargs)\n           ^^^^^^^^^^^^^^^^^^^^^^^^^^^^^^^^^^^^^^^^^^^^\n  File "/app/bin/bazarr/../libs/requests/api.py", line 59, in request\n    return session.request(method=method, url=url, **kwargs)\n           ^^^^^^^^^^^^^^^^^^^^^^^^^^^^^^^^^^^^^^^^^^^^^^^^^\n  File "/app/bin/bazarr/../libs/requests/sessions.py", line 587, in request\n    resp = self.send(prep, **send_kwargs)\n           ^^^^^^^^^^^^^^^^^^^^^^^^^^^^^^\n  File "/app/bin/bazarr/../libs/requests/sessions.py", line 701, in send\n    r = adapter.send(request, **kwargs)\n        ^^^^^^^^^^^^^^^^^^^^^^^^^^^^^^^\n  File "/app/bin/bazarr/../libs/requests/adapters.py", line 565, in send\n    raise ConnectionError(e, request=request)\nrequests.exceptions.ConnectionError: HTTPSConnectionPool(host=\'api.github.com\', port=443): Max retries exceeded with url: /repos/morpheus65535/Bazarr/releases?per_page=100 (Caused by NewConnectionError(\'<urllib3.connection.HTTPSConnection object at 0x7fff726fb4d0>: Failed to establish a new connection: [Errno -3] Try again\'))'|
2024-05-03 18:13:14|ERROR   |root                            |Error trying to get announcements from Github. Connection Error.|'Traceback (most recent call last):\n  File "/app/bin/bazarr/../libs/urllib3/connection.py", line 174, in _new_conn\n    conn = connection.create_connection(\n           ^^^^^^^^^^^^^^^^^^^^^^^^^^^^^\n  File "/app/bin/bazarr/../libs/subliminal_patch/http.py", line 325, in patched_create_connection\n    return _orig_create_connection(address, *args, **kwargs)\n           ^^^^^^^^^^^^^^^^^^^^^^^^^^^^^^^^^^^^^^^^^^^^^^^^^\n  File "/app/bin/bazarr/../libs/urllib3/util/connection.py", line 72, in create_connection\n    for res in socket.getaddrinfo(host, port, family, socket.SOCK_STREAM):\n               ^^^^^^^^^^^^^^^^^^^^^^^^^^^^^^^^^^^^^^^^^^^^^^^^^^^^^^^^^^\n  File "/usr/lib/python3.11/socket.py", line 962, in getaddrinfo\n    for res in _socket.getaddrinfo(host, port, family, type, proto, flags):\n               ^^^^^^^^^^^^^^^^^^^^^^^^^^^^^^^^^^^^^^^^^^^^^^^^^^^^^^^^^^^\nsocket.gaierror: [Errno -3] Try again\n\nDuring handling of the above exception, another exception occurred:\n\nTraceback (most recent call last):\n  File "/app/bin/bazarr/../libs/urllib3/connectionpool.py", line 703, in urlopen\n    httplib_response = self._make_request(\n                       ^^^^^^^^^^^^^^^^^^^\n  File "/app/bin/bazarr/../libs/urllib3/connectionpool.py", line 386, in _make_request\n    self._validate_conn(conn)\n  File "/app/bin/bazarr/../libs/urllib3/connectionpool.py", line 1042, in _validate_conn\n    conn.connect()\n  File "/app/bin/bazarr/../libs/urllib3/connection.py", line 358, in connect\n    self.sock = conn = self._new_conn()\n                       ^^^^^^^^^^^^^^^^\n  File "/app/bin/bazarr/../libs/urllib3/connection.py", line 186, in _new_conn\n    raise NewConnectionError(\nurllib3.exceptions.NewConnectionError: <urllib3.connection.HTTPSConnection object at 0x7fff706ac110>: Failed to establish a new connection: [Errno -3] Try again\n\nDuring handling of the above exception, another exception occurred:\n\nTraceback (most recent call last):\n  File "/app/bin/bazarr/../libs/requests/adapters.py", line 489, in send\n    resp = conn.urlopen(\n           ^^^^^^^^^^^^^\n  File "/app/bin/bazarr/../libs/urllib3/connectionpool.py", line 787, in urlopen\n    retries = retries.increment(\n              ^^^^^^^^^^^^^^^^^^\n  File "/app/bin/bazarr/../libs/urllib3/util/retry.py", line 592, in increment\n    raise MaxRetryError(_pool, url, error or ResponseError(cause))\nurllib3.exceptions.MaxRetryError: HTTPSConnectionPool(host=\'raw.githubusercontent.com\', port=443): Max retries exceeded with url: /morpheus65535/bazarr-binaries/master/announcements.json (Caused by NewConnectionError(\'<urllib3.connection.HTTPSConnection object at 0x7fff706ac110>: Failed to establish a new connection: [Errno -3] Try again\'))\n\nDuring handling of the above exception, another exception occurred:\n\nTraceback (most recent call last):\n  File "/app/bin/bazarr/app/announcements.py", line 46, in get_announcements_to_file\n    r = requests.get("https://raw.githubusercontent.com/morpheus65535/bazarr-binaries/master/announcements.json",\n        ^^^^^^^^^^^^^^^^^^^^^^^^^^^^^^^^^^^^^^^^^^^^^^^^^^^^^^^^^^^^^^^^^^^^^^^^^^^^^^^^^^^^^^^^^^^^^^^^^^^^^^^^^\n  File "/app/bin/bazarr/../libs/requests/api.py", line 73, in get\n    return request("get", url, params=params, **kwargs)\n           ^^^^^^^^^^^^^^^^^^^^^^^^^^^^^^^^^^^^^^^^^^^^\n  File "/app/bin/bazarr/../libs/requests/api.py", line 59, in request\n    return session.request(method=method, url=url, **kwargs)\n           ^^^^^^^^^^^^^^^^^^^^^^^^^^^^^^^^^^^^^^^^^^^^^^^^^\n  File "/app/bin/bazarr/../libs/requests/sessions.py", line 587, in request\n    resp = self.send(prep, **send_kwargs)\n           ^^^^^^^^^^^^^^^^^^^^^^^^^^^^^^\n  File "/app/bin/bazarr/../libs/requests/sessions.py", line 701, in send\n    r = adapter.send(request, **kwargs)\n        ^^^^^^^^^^^^^^^^^^^^^^^^^^^^^^^\n  File "/app/bin/bazarr/../libs/requests/adapters.py", line 565, in send\n    raise ConnectionError(e, request=request)\nrequests.exceptions.ConnectionError: HTTPSConnectionPool(host=\'raw.githubusercontent.com\', port=443): Max retries exceeded with url: /morpheus65535/bazarr-binaries/master/announcements.json (Caused by NewConnectionError(\'<urllib3.connection.HTTPSConnection object at 0x7fff706ac110>: Failed to establish a new connection: [Errno -3] Try again\'))'|
2024-05-03 18:13:14|INFO    |root                            |BAZARR trying to connect to Sonarr SignalR feed...|
2024-05-03 18:13:14|INFO    |root                            |BAZARR trying to connect to Radarr SignalR feed...|
2024-05-03 18:13:14|INFO    |root                            |BAZARR is started and waiting for request on http://***.***.***.***:6767|
2024-05-03 18:13:14|INFO    |root                            |BAZARR SignalR client for Radarr is connected and waiting for events.|
2024-05-03 18:13:14|INFO    |root                            |BAZARR SignalR client for Sonarr is connected and waiting for events.|
2024-05-03 18:13:15|ERROR   |apscheduler.executors.default   |Job "update_movies (trigger: date[2024-05-03 18:13:14 CEST], next run at: 2024-05-03 18:13:14 CEST)" raised an exception|'Traceback (most recent call last):\n  File "/app/bin/bazarr/../libs/apscheduler/executors/base.py", line 125, in run_job\n    retval = job.func(*job.args, **job.kwargs)\n             ^^^^^^^^^^^^^^^^^^^^^^^^^^^^^^^^^\n  File "/app/bin/bazarr/radarr/sync/movies.py", line 196, in update_movies\n    trace(f"Skipped {files_missing} file missing movies out of {i}")\n                                                                ^\nUnboundLocalError: cannot access local variable \'i\' where it is not associated with a value'|
2024-05-03 23:13:56|INFO    |root                            |BAZARR Finished searching for missing Movies Subtitles. Check History for more information.|
2024-05-03 23:43:16|INFO    |root                            |BAZARR Finished searching for missing Series Subtitles. Check History for more information.|
